from DDBpy_auth.ddb_auth import DDBAuth, DDB_Exception
